Traceback (most recent call last):
  File "/home/ryoshio/estudoFastAPI/dunossauro/fast_zero/.venv/lib/python3.11/site-packages/uvicorn/protocols/http/httptools_impl.py", line 409, in run_asgi
    result = await app(  # type: ignore[func-returns-value]
             ^^^^^^^^^^^^^^^^^^^^^^^^^^^^^^^^^^^^^^^^^^^^^^
  File "/home/ryoshio/estudoFastAPI/dunossauro/fast_zero/.venv/lib/python3.11/site-packages/uvicorn/middleware/proxy_headers.py", line 60, in __call__
    return await self.app(scope, receive, send)
           ^^^^^^^^^^^^^^^^^^^^^^^^^^^^^^^^^^^^
  File "/home/ryoshio/estudoFastAPI/dunossauro/fast_zero/.venv/lib/python3.11/site-packages/fastapi/applications.py", line 1054, in __call__
    await super().__call__(scope, receive, send)
  File "/home/ryoshio/estudoFastAPI/dunossauro/fast_zero/.venv/lib/python3.11/site-packages/starlette/applications.py", line 113, in __call__
    await self.middleware_stack(scope, receive, send)
  File "/home/ryoshio/estudoFastAPI/dunossauro/fast_zero/.venv/lib/python3.11/site-packages/starlette/middleware/errors.py", line 187, in __call__
    raise exc
  File "/home/ryoshio/estudoFastAPI/dunossauro/fast_zero/.venv/lib/python3.11/site-packages/starlette/middleware/errors.py", line 165, in __call__
    await self.app(scope, receive, _send)
  File "/home/ryoshio/estudoFastAPI/dunossauro/fast_zero/.venv/lib/python3.11/site-packages/starlette/middleware/exceptions.py", line 62, in __call__
    await wrap_app_handling_exceptions(self.app, conn)(scope, receive, send)
  File "/home/ryoshio/estudoFastAPI/dunossauro/fast_zero/.venv/lib/python3.11/site-packages/starlette/_exception_handler.py", line 53, in wrapped_app
    raise exc
  File "/home/ryoshio/estudoFastAPI/dunossauro/fast_zero/.venv/lib/python3.11/site-packages/starlette/_exception_handler.py", line 42, in wrapped_app
    await app(scope, receive, sender)
  File "/home/ryoshio/estudoFastAPI/dunossauro/fast_zero/.venv/lib/python3.11/site-packages/starlette/routing.py", line 715, in __call__
    await self.middleware_stack(scope, receive, send)
  File "/home/ryoshio/estudoFastAPI/dunossauro/fast_zero/.venv/lib/python3.11/site-packages/starlette/routing.py", line 735, in app
    await route.handle(scope, receive, send)
  File "/home/ryoshio/estudoFastAPI/dunossauro/fast_zero/.venv/lib/python3.11/site-packages/starlette/routing.py", line 288, in handle
    await self.app(scope, receive, send)
  File "/home/ryoshio/estudoFastAPI/dunossauro/fast_zero/.venv/lib/python3.11/site-packages/starlette/routing.py", line 76, in app
    await wrap_app_handling_exceptions(app, request)(scope, receive, send)
  File "/home/ryoshio/estudoFastAPI/dunossauro/fast_zero/.venv/lib/python3.11/site-packages/starlette/_exception_handler.py", line 53, in wrapped_app
    raise exc
  File "/home/ryoshio/estudoFastAPI/dunossauro/fast_zero/.venv/lib/python3.11/site-packages/starlette/_exception_handler.py", line 42, in wrapped_app
    await app(scope, receive, sender)
  File "/home/ryoshio/estudoFastAPI/dunossauro/fast_zero/.venv/lib/python3.11/site-packages/starlette/routing.py", line 73, in app
    response = await f(request)
               ^^^^^^^^^^^^^^^^
  File "/home/ryoshio/estudoFastAPI/dunossauro/fast_zero/.venv/lib/python3.11/site-packages/fastapi/routing.py", line 327, in app
    content = await serialize_response(
              ^^^^^^^^^^^^^^^^^^^^^^^^^
  File "/home/ryoshio/estudoFastAPI/dunossauro/fast_zero/.venv/lib/python3.11/site-packages/fastapi/routing.py", line 176, in serialize_response
    raise ResponseValidationError(
fastapi.exceptions.ResponseValidationError: 1 validation errors:
  {'type': 'model_attributes_type', 'loc': ('response',), 'msg': 'Input should be a valid dictionary or object to extract fields from', 'input': None}